Workbook

Sheet 📋 Raw Data
A1: # | B1: الشهر | C1: المنطقة | D1: المنتج | E1: البائع | F1: الكمية | G1: سعر الوحدة (ج.م) | H1: إجمالي المبيعات (ج.م) | I1: تكلفة البضاعة (ج.م) | J1: صافي الربح (ج.م) | K1: نسبة الربح %
A2: 1 | B2: يناير | C2: الشمال | D2: لابتوب برو | E2: محمود حسن | F2: 18 | G2: 4340.89 | H2: =F2*G2 -> 78136.02 | I2: =F2*G2*0.62 -> 48444.332 | J2: =H2-I2 -> 29691.688 | K2: =IF(H2=0,0,J2/H2) -> 0.38
A3: 2 | B3: يناير | C3: الوسط | D3: لابتوب برو | E3: أحمد محمد | F3: 40 | G3: 4519.73 | H3: =F3*G3 -> 180789.2 | I3: =F3*G3*0.62 -> 112089.3 | J3: =H3-I3 -> 68699.896 | K3: =IF(H3=0,0,J3/H3) -> 0.38
A4: 3 | B4: يناير | C4: الشمال | D4: لابتوب برو | E4: سارة علي | F4: 17 | G4: 4594.82 | H4: =F4*G4 -> 78111.94 | I4: =F4*G4*0.62 -> 48429.403 | J4: =H4-I4 -> 29682.537 | K4: =IF(H4=0,0,J4/H4) -> 0.38
A5: 4 | B5: يناير | C5: الوسط | D5: لابتوب برو | E5: سارة علي | F5: 37 | G5: 4517.57 | H5: =F5*G5 -> 167150.09 | I5: =F5*G5*0.62 -> 103633.06 | J5: =H5-I5 -> 63517.034 | K5: =IF(H5=0,0,J5/H5) -> 0.38
A6: 5 | B6: يناير | C6: الوسط | D6: سماعات لاسلكية | E6: محمود حسن | F6: 3 | G6: 696.64 | H6: =F6*G6 -> 2089.92 | I6: =F6*G6*0.45 -> 940.464 | J6: =H6-I6 -> 1149.456 | K6: =IF(H6=0,0,J6/H6) -> 0.55
A7: 6 | B7: يناير | C7: الغرب | D7: هاتف سمارت | E7: محمود حسن | F7: 20 | G7: 2663.07 | H7: =F7*G7 -> 53261.4 | I7: =F7*G7*0.58 -> 30891.612 | J7: =H7-I7 -> 22369.788 | K7: =IF(H7=0,0,J7/H7) -> 0.42
A8: 7 | B8: يناير | C8: الشمال | D8: تابلت إكس | E8: أحمد محمد | F8: 27 | G8: 1784.75 | H8: =F8*G8 -> 48188.25 | I8: =F8*G8*0.55 -> 26503.538 | J8: =H8-I8 -> 21684.712 | K8: =IF(H8=0,0,J8/H8) -> 0.45
A9: 8 | B9: يناير | C9: الوسط | D9: تابلت إكس | E9: محمود حسن | F9: 5 | G9: 2025.3 | H9: =F9*G9 -> 10126.5 | I9: =F9*G9*0.55 -> 5569.575 | J9: =H9-I9 -> 4556.925 | K9: =IF(H9=0,0,J9/H9) -> 0.45
A10: 9 | B10: يناير | C10: الشمال | D10: ساعة ذكية | E10: نورا إبراهيم | F10: 8 | G10: 1236.49 | H10: =F10*G10 -> 9891.92 | I10: =F10*G10*0.5 -> 4945.96 | J10: =H10-I10 -> 4945.96 | K10: =IF(H10=0,0,J10/H10) -> 0.5
A11: 10 | B11: يناير | C11: الشرق | D11: ساعة ذكية | E11: خالد يوسف | F11: 15 | G11: 1273.1 | H11: =F11*G11 -> 19096.5 | I11: =F11*G11*0.5 -> 9548.25 | J11: =H11-I11 -> 9548.25 | K11: =IF(H11=0,0,J11/H11) -> 0.5
A12: 11 | B12: يناير | C12: الجنوب | D12: لابتوب برو | E12: محمود حسن | F12: 8 | G12: 4909.79 | H12: =F12*G12 -> 39278.32 | I12: =F12*G12*0.62 -> 24352.558 | J12: =H12-I12 -> 14925.762 | K12: =IF(H12=0,0,J12/H12) -> 0.38
A13: 12 | B13: يناير | C13: الغرب | D13: لابتوب برو | E13: محمود حسن | F13: 32 | G13: 4712.12 | H13: =F13*G13 -> 150787.84 | I13: =F13*G13*0.62 -> 93488.461 | J13: =H13-I13 -> 57299.379 | K13: =IF(H13=0,0,J13/H13) -> 0.38
A14: 13 | B14: يناير | C14: الجنوب | D14: تابلت إكس | E14: محمود حسن | F14: 25 | G14: 1827.61 | H14: =F14*G14 -> 45690.25 | I14: =F14*G14*0.55 -> 25129.638 | J14: =H14-I14 -> 20560.612 | K14: =IF(H14=0,0,J14/H14) -> 0.45
A15: 14 | B15: يناير | C15: الشمال | D15: تابلت إكس | E15: خالد يوسف | F15: 13 | G15: 1950.97 | H15: =F15*G15 -> 25362.61 | I15: =F15*G15*0.55 -> 13949.436 | J15: =H15-I15 -> 11413.174 | K15: =IF(H15=0,0,J15/H15) -> 0.45
A16: 15 | B16: يناير | C16: الجنوب | D16: هاتف سمارت | E16: نورا إبراهيم | F16: 27 | G16: 2727.17 | H16: =F16*G16 -> 73633.59 | I16: =F16*G16*0.58 -> 42707.482 | J16: =H16-I16 -> 30926.108 | K16: =IF(H16=0,0,J16/H16) -> 0.42
A17: 16 | B17: يناير | C17: الجنوب | D17: ساعة ذكية | E17: محمود حسن | F17: 6 | G17: 1158.97 | H17: =F17*G17 -> 6953.82 | I17: =F17*G17*0.5 -> 3476.91 | J17: =H17-I17 -> 3476.91 | K17: =IF(H17=0,0,J17/H17) -> 0.5
A18: 17 | B18: يناير | C18: الشرق | D18: لابتوب برو | E18: نورا إبراهيم | F18: 20 | G18: 4199.57 | H18: =F18*G18 -> 83991.4 | I18: =F18*G18*0.62 -> 52074.668 | J18: =H18-I18 -> 31916.732 | K18: =IF(H18=0,0,J18/H18) -> 0.38
A19: 18 | B19: يناير | C19: الشرق | D19: ساعة ذكية | E19: سارة علي | F19: 34 | G19: 1198.95 | H19: =F19*G19 -> 40764.3 | I19: =F19*G19*0.5 -> 20382.15 | J19: =H19-I19 -> 20382.15 | K19: =IF(H19=0,0,J19/H19) -> 0.5
A20: 19 | B20: فبراير | C20: الجنوب | D20: سماعات لاسلكية | E20: محمود حسن | F20: 11 | G20: 630.06 | H20: =F20*G20 -> 6930.66 | I20: =F20*G20*0.45 -> 3118.797 | J20: =H20-I20 -> 3811.863 | K20: =IF(H20=0,0,J20/H20) -> 0.55
A21: 20 | B21: فبراير | C21: الوسط | D21: ساعة ذكية | E21: محمود حسن | F21: 40 | G21: 1206.82 | H21: =F21*G21 -> 48272.8 | I21: =F21*G21*0.5 -> 24136.4 | J21: =H21-I21 -> 24136.4 | K21: =IF(H21=0,0,J21/H21) -> 0.5
A22: 21 | B22: فبراير | C22: الغرب | D22: ساعة ذكية | E22: محمود حسن | F22: 17 | G22: 1343.36 | H22: =F22*G22 -> 22837.12 | I22: =F22*G22*0.5 -> 11418.56 | J22: =H22-I22 -> 11418.56 | K22: =IF(H22=0,0,J22/H22) -> 0.5
A23: 22 | B23: فبراير | C23: الوسط | D23: هاتف سمارت | E23: نورا إبراهيم | F23: 8 | G23: 2999.24 | H23: =F23*G23 -> 23993.92 | I23: =F23*G23*0.58 -> 13916.474 | J23: =H23-I23 -> 10077.446 | K23: =IF(H23=0,0,J23/H23) -> 0.42
A24: 23 | B24: فبراير | C24: الجنوب | D24: لابتوب برو | E24: سارة علي | F24: 30 | G24: 4676.77 | H24: =F24*G24 -> 140303.1 | I24: =F24*G24*0.62 -> 86987.922 | J24: =H24-I24 -> 53315.178 | K24: =IF(H24=0,0,J24/H24) -> 0.38
A25: 24 | B25: فبراير | C25: الغرب | D25: سماعات لاسلكية | E25: خالد يوسف | F25: 32 | G25: 666.78 | H25: =F25*G25 -> 21336.96 | I25: =F25*G25*0.45 -> 9601.632 | J25: =H25-I25 -> 11735.328 | K25: =IF(H25=0,0,J25/H25) -> 0.55
A26: 25 | B26: فبراير | C26: الشمال | D26: ساعة ذكية | E26: أحمد محمد | F26: 37 | G26: 1284.21 | H26: =F26*G26 -> 47515.77 | I26: =F26*G26*0.5 -> 23757.885 | J26: =H26-I26 -> 23757.885 | K26: =IF(H26=0,0,J26/H26) -> 0.5
A27: 26 | B27: فبراير | C27: الشمال | D27: تابلت إكس | E27: محمود حسن | F27: 30 | G27: 1808.1 | H27: =F27*G27 -> 54243 | I27: =F27*G27*0.55 -> 29833.65 | J27: =H27-I27 -> 24409.35 | K27: =IF(H27=0,0,J27/H27) -> 0.45
A28: 27 | B28: فبراير | C28: الشرق | D28: لابتوب برو | E28: خالد يوسف | F28: 14 | G28: 4596.91 | H28: =F28*G28 -> 64356.74 | I28: =F28*G28*0.62 -> 39901.179 | J28: =H28-I28 -> 24455.561 | K28: =IF(H28=0,0,J28/H28) -> 0.38
A29: 28 | B29: فبراير | C29: الشرق | D29: لابتوب برو | E29: خالد يوسف | F29: 15 | G29: 4277.56 | H29: =F29*G29 -> 64163.4 | I29: =F29*G29*0.62 -> 39781.308 | J29: =H29-I29 -> 24382.092 | K29: =IF(H29=0,0,J29/H29) -> 0.38
A30: 29 | B30: فبراير | C30: الوسط | D30: هاتف سمارت | E30: خالد يوسف | F30: 3 | G30: 2911.41 | H30: =F30*G30 -> 8734.23 | I30: =F30*G30*0.58 -> 5065.8534 | J30: =H30-I30 -> 3668.3766 | K30: =IF(H30=0,0,J30/H30) -> 0.42
A31: 30 | B31: فبراير | C31: الشمال | D31: سماعات لاسلكية | E31: أحمد محمد | F31: 26 | G31: 712.23 | H31: =F31*G31 -> 18517.98 | I31: =F31*G31*0.45 -> 8333.091 | J31: =H31-I31 -> 10184.889 | K31: =IF(H31=0,0,J31/H31) -> 0.55
A32: 31 | B32: فبراير | C32: الجنوب | D32: تابلت إكس | E32: أحمد محمد | F32: 18 | G32: 2081.64 | H32: =F32*G32 -> 37469.52 | I32: =F32*G32*0.55 -> 20608.236 | J32: =H32-I32 -> 16861.284 | K32: =IF(H32=0,0,J32/H32) -> 0.45
A33: 32 | B33: فبراير | C33: الشمال | D33: لابتوب برو | E33: نورا إبراهيم | F33: 7 | G33: 5020.19 | H33: =F33*G33 -> 35141.33 | I33: =F33*G33*0.62 -> 21787.625 | J33: =H33-I33 -> 13353.705 | K33: =IF(H33=0,0,J33/H33) -> 0.38
A34: 33 | B34: فبراير | C34: الجنوب | D34: ساعة ذكية | E34: سارة علي | F34: 33 | G34: 1331.24 | H34: =F34*G34 -> 43930.92 | I34: =F34*G34*0.5 -> 21965.46 | J34: =H34-I34 -> 21965.46 | K34: =IF(H34=0,0,J34/H34) -> 0.5
A35: 34 | B35: فبراير | C35: الشرق | D35: هاتف سمارت | E35: خالد يوسف | F35: 30 | G35: 3116.04 | H35: =F35*G35 -> 93481.2 | I35: =F35*G35*0.58 -> 54219.096 | J35: =H35-I35 -> 39262.104 | K35: =IF(H35=0,0,J35/H35) -> 0.42
A36: 35 | B36: فبراير | C36: الجنوب | D36: ساعة ذكية | E36: محمود حسن | F36: 28 | G36: 1342.84 | H36: =F36*G36 -> 37599.52 | I36: =F36*G36*0.5 -> 18799.76 | J36: =H36-I36 -> 18799.76 | K36: =IF(H36=0,0,J36/H36) -> 0.5
A37: 36 | B37: فبراير | C37: الغرب | D37: تابلت إكس | E37: خالد يوسف | F37: 31 | G37: 1793.98 | H37: =F37*G37 -> 55613.38 | I37: =F37*G37*0.55 -> 30587.359 | J37: =H37-I37 -> 25026.021 | K37: =IF(H37=0,0,J37/H37) -> 0.45
A38: 37 | B38: مارس | C38: الشمال | D38: هاتف سمارت | E38: محمود حسن | F38: 4 | G38: 2905.45 | H38: =F38*G38 -> 11621.8 | I38: =F38*G38*0.58 -> 6740.644 | J38: =H38-I38 -> 4881.156 | K38: =IF(H38=0,0,J38/H38) -> 0.42
A39: 38 | B39: مارس | C39: الوسط | D39: هاتف سمارت | E39: سارة علي | F39: 3 | G39: 2615.76 | H39: =F39*G39 -> 7847.28 | I39: =F39*G39*0.58 -> 4551.4224 | J39: =H39-I39 -> 3295.8576 | K39: =IF(H39=0,0,J39/H39) -> 0.42
A40: 39 | B40: مارس | C40: الجنوب | D40: لابتوب برو | E40: أحمد محمد | F40: 5 | G40: 4913.67 | H40: =F40*G40 -> 24568.35 | I40: =F40*G40*0.62 -> 15232.377 | J40: =H40-I40 -> 9335.973 | K40: =IF(H40=0,0,J40/H40) -> 0.38
...

Sheet 📊 Dashboard
A1: 📊 لوحة تحليل المبيعات – 2025
A3: تقرير سنوي شامل | إجمالي المبيعات – المنتجات – المناطق – البائعون
A5: 💰 إجمالي المبيعات | D5: 📦 عدد الصفقات | G5: 🏆 صافي الربح | J5: 📈 متوسط نسبة الربح
A6: =SUM('📋 Raw Data'!H2:H217) -> 10482342 | D6: =COUNTA('📋 Raw Data'!A2:A217) -> 216 | G6: =SUM('📋 Raw Data'!J2:J217) -> 4483401 | J6: =AVERAGE('📋 Raw Data'!K2:K217) -> 0.46115741
A9: 📅 المبيعات الشهرية | E9: 🛒 أداء المنتجات | I9: 🗺️ أداء المناطق
A10: الشهر | B10: المبيعات (ج.م) | C10: الربح (ج.م) | E10: المنتج | F10: المبيعات (ج.م) | G10: الكمية | I10: المنطقة | J10: المبيعات (ج.م) | K10: عدد الصفقات
A11: يناير | B11: =SUMPRODUCT(('📋 Raw Data'!B$2:B$217=A11)*'📋 Raw Data'!H$2:H$217) -> 1113303.9 | C11: =SUMPRODUCT(('📋 Raw Data'!B$2:B$217=A11)*'📋 Raw Data'!J$2:J$217) -> 446747.07 | E11: لابتوب برو | F11: =SUMPRODUCT(('📋 Raw Data'!D$2:D$217=E11)*'📋 Raw Data'!H$2:H$217) -> 4212699.1 | G11: =SUMPRODUCT(('📋 Raw Data'!D$2:D$217=E11)*'📋 Raw Data'!F$2:F$217) -> 914 | I11: الشمال | J11: =SUMPRODUCT(('📋 Raw Data'!C$2:C$217=I11)*'📋 Raw Data'!H$2:H$217) -> 1668953.3 | K11: =COUNTIF('📋 Raw Data'!C$2:C$217,I11) -> 35
A12: فبراير | B12: =SUMPRODUCT(('📋 Raw Data'!B$2:B$217=A12)*'📋 Raw Data'!H$2:H$217) -> 824441.55 | C12: =SUMPRODUCT(('📋 Raw Data'!B$2:B$217=A12)*'📋 Raw Data'!J$2:J$217) -> 360621.26 | E12: هاتف سمارت | F12: =SUMPRODUCT(('📋 Raw Data'!D$2:D$217=E12)*'📋 Raw Data'!H$2:H$217) -> 2442295.1 | G12: =SUMPRODUCT(('📋 Raw Data'!D$2:D$217=E12)*'📋 Raw Data'!F$2:F$217) -> 872 | I12: الجنوب | J12: =SUMPRODUCT(('📋 Raw Data'!C$2:C$217=I12)*'📋 Raw Data'!H$2:H$217) -> 1903985.1 | K12: =COUNTIF('📋 Raw Data'!C$2:C$217,I12) -> 41
A13: مارس | B13: =SUMPRODUCT(('📋 Raw Data'!B$2:B$217=A13)*'📋 Raw Data'!H$2:H$217) -> 942205.25 | C13: =SUMPRODUCT(('📋 Raw Data'!B$2:B$217=A13)*'📋 Raw Data'!J$2:J$217) -> 385904.52 | E13: تابلت إكس | F13: =SUMPRODUCT(('📋 Raw Data'!D$2:D$217=E13)*'📋 Raw Data'!H$2:H$217) -> 1837139.6 | G13: =SUMPRODUCT(('📋 Raw Data'!D$2:D$217=E13)*'📋 Raw Data'!F$2:F$217) -> 952 | I13: الشرق | J13: =SUMPRODUCT(('📋 Raw Data'!C$2:C$217=I13)*'📋 Raw Data'!H$2:H$217) -> 1983703.5 | K13: =COUNTIF('📋 Raw Data'!C$2:C$217,I13) -> 43
A14: أبريل | B14: =SUMPRODUCT(('📋 Raw Data'!B$2:B$217=A14)*'📋 Raw Data'!H$2:H$217) -> 744150.31 | C14: =SUMPRODUCT(('📋 Raw Data'!B$2:B$217=A14)*'📋 Raw Data'!J$2:J$217) -> 326116.44 | E14: سماعات لاسلكية | F14: =SUMPRODUCT(('📋 Raw Data'!D$2:D$217=E14)*'📋 Raw Data'!H$2:H$217) -> 699892.69 | G14: =SUMPRODUCT(('📋 Raw Data'!D$2:D$217=E14)*'📋 Raw Data'!F$2:F$217) -> 1058 | I14: الغرب | J14: =SUMPRODUCT(('📋 Raw Data'!C$2:C$217=I14)*'📋 Raw Data'!H$2:H$217) -> 2372972.3 | K14: =COUNTIF('📋 Raw Data'!C$2:C$217,I14) -> 46
A15: مايو | B15: =SUMPRODUCT(('📋 Raw Data'!B$2:B$217=A15)*'📋 Raw Data'!H$2:H$217) -> 988681.97 | C15: =SUMPRODUCT(('📋 Raw Data'!B$2:B$217=A15)*'📋 Raw Data'!J$2:J$217) -> 416647.19 | E15: ساعة ذكية | F15: =SUMPRODUCT(('📋 Raw Data'!D$2:D$217=E15)*'📋 Raw Data'!H$2:H$217) -> 1290315.3 | G15: =SUMPRODUCT(('📋 Raw Data'!D$2:D$217=E15)*'📋 Raw Data'!F$2:F$217) -> 1049 | I15: الوسط | J15: =SUMPRODUCT(('📋 Raw Data'!C$2:C$217=I15)*'📋 Raw Data'!H$2:H$217) -> 2552727.6 | K15: =COUNTIF('📋 Raw Data'!C$2:C$217,I15) -> 51
A16: يونيو | B16: =SUMPRODUCT(('📋 Raw Data'!B$2:B$217=A16)*'📋 Raw Data'!H$2:H$217) -> 815440.57 | C16: =SUMPRODUCT(('📋 Raw Data'!B$2:B$217=A16)*'📋 Raw Data'!J$2:J$217) -> 358943.43
A17: يوليو | B17: =SUMPRODUCT(('📋 Raw Data'!B$2:B$217=A17)*'📋 Raw Data'!H$2:H$217) -> 731338.44 | C17: =SUMPRODUCT(('📋 Raw Data'!B$2:B$217=A17)*'📋 Raw Data'!J$2:J$217) -> 318055.15
A18: أغسطس | B18: =SUMPRODUCT(('📋 Raw Data'!B$2:B$217=A18)*'📋 Raw Data'!H$2:H$217) -> 790221.39 | C18: =SUMPRODUCT(('📋 Raw Data'!B$2:B$217=A18)*'📋 Raw Data'!J$2:J$217) -> 364579.72
A19: سبتمبر | B19: =SUMPRODUCT(('📋 Raw Data'!B$2:B$217=A19)*'📋 Raw Data'!H$2:H$217) -> 821661.43 | C19: =SUMPRODUCT(('📋 Raw Data'!B$2:B$217=A19)*'📋 Raw Data'!J$2:J$217) -> 345696.05
A20: أكتوبر | B20: =SUMPRODUCT(('📋 Raw Data'!B$2:B$217=A20)*'📋 Raw Data'!H$2:H$217) -> 913664.59 | C20: =SUMPRODUCT(('📋 Raw Data'!B$2:B$217=A20)*'📋 Raw Data'!J$2:J$217) -> 384383.43
A21: نوفمبر | B21: =SUMPRODUCT(('📋 Raw Data'!B$2:B$217=A21)*'📋 Raw Data'!H$2:H$217) -> 929140.14 | C21: =SUMPRODUCT(('📋 Raw Data'!B$2:B$217=A21)*'📋 Raw Data'!J$2:J$217) -> 408642.74
A22: ديسمبر | B22: =SUMPRODUCT(('📋 Raw Data'!B$2:B$217=A22)*'📋 Raw Data'!H$2:H$217) -> 868092.28 | C22: =SUMPRODUCT(('📋 Raw Data'!B$2:B$217=A22)*'📋 Raw Data'!J$2:J$217) -> 367064.04
A23: 👤 أداء فريق المبيعات
A24: البائع | B24: إجمالي مبيعاته (ج.م) | C24: عدد صفقاته
A25: أحمد محمد | B25: =SUMPRODUCT(('📋 Raw Data'!E$2:E$217=A25)*'📋 Raw Data'!H$2:H$217) -> 2165301.7 | C25: =COUNTIF('📋 Raw Data'!E$2:E$217,A25) -> 43
A26: سارة علي | B26: =SUMPRODUCT(('📋 Raw Data'!E$2:E$217=A26)*'📋 Raw Data'!H$2:H$217) -> 2813342.1 | C26: =COUNTIF('📋 Raw Data'!E$2:E$217,A26) -> 48
A27: محمود حسن | B27: =SUMPRODUCT(('📋 Raw Data'!E$2:E$217=A27)*'📋 Raw Data'!H$2:H$217) -> 2290290.8 | C27: =COUNTIF('📋 Raw Data'!E$2:E$217,A27) -> 49
A28: نورا إبراهيم | B28: =SUMPRODUCT(('📋 Raw Data'!E$2:E$217=A28)*'📋 Raw Data'!H$2:H$217) -> 1612838.1 | C28: =COUNTIF('📋 Raw Data'!E$2:E$217,A28) -> 36
A29: خالد يوسف | B29: =SUMPRODUCT(('📋 Raw Data'!E$2:E$217=A29)*'📋 Raw Data'!H$2:H$217) -> 1600569.2 | C29: =COUNTIF('📋 Raw Data'!E$2:E$217,A29) -> 40

Sheet 📈 الرسوم البيانية
A1: 📈 الرسوم البيانية التحليلية
A4: بيانات الرسم البياني الشهري
A5: الشهر | B5: المبيعات | C5: الربح
A6: يناير | B6: =SUMPRODUCT(('📋 Raw Data'!B$2:B$217=A6)*'📋 Raw Data'!H$2:H$217) -> 1113303.9 | C6: =SUMPRODUCT(('📋 Raw Data'!B$2:B$217=A6)*'📋 Raw Data'!J$2:J$217) -> 446747.07
A7: فبراير | B7: =SUMPRODUCT(('📋 Raw Data'!B$2:B$217=A7)*'📋 Raw Data'!H$2:H$217) -> 824441.55 | C7: =SUMPRODUCT(('📋 Raw Data'!B$2:B$217=A7)*'📋 Raw Data'!J$2:J$217) -> 360621.26
A8: مارس | B8: =SUMPRODUCT(('📋 Raw Data'!B$2:B$217=A8)*'📋 Raw Data'!H$2:H$217) -> 942205.25 | C8: =SUMPRODUCT(('📋 Raw Data'!B$2:B$217=A8)*'📋 Raw Data'!J$2:J$217) -> 385904.52
A9: أبريل | B9: =SUMPRODUCT(('📋 Raw Data'!B$2:B$217=A9)*'📋 Raw Data'!H$2:H$217) -> 744150.31 | C9: =SUMPRODUCT(('📋 Raw Data'!B$2:B$217=A9)*'📋 Raw Data'!J$2:J$217) -> 326116.44
A10: مايو | B10: =SUMPRODUCT(('📋 Raw Data'!B$2:B$217=A10)*'📋 Raw Data'!H$2:H$217) -> 988681.97 | C10: =SUMPRODUCT(('📋 Raw Data'!B$2:B$217=A10)*'📋 Raw Data'!J$2:J$217) -> 416647.19
A11: يونيو | B11: =SUMPRODUCT(('📋 Raw Data'!B$2:B$217=A11)*'📋 Raw Data'!H$2:H$217) -> 815440.57 | C11: =SUMPRODUCT(('📋 Raw Data'!B$2:B$217=A11)*'📋 Raw Data'!J$2:J$217) -> 358943.43
A12: يوليو | B12: =SUMPRODUCT(('📋 Raw Data'!B$2:B$217=A12)*'📋 Raw Data'!H$2:H$217) -> 731338.44 | C12: =SUMPRODUCT(('📋 Raw Data'!B$2:B$217=A12)*'📋 Raw Data'!J$2:J$217) -> 318055.15
A13: أغسطس | B13: =SUMPRODUCT(('📋 Raw Data'!B$2:B$217=A13)*'📋 Raw Data'!H$2:H$217) -> 790221.39 | C13: =SUMPRODUCT(('📋 Raw Data'!B$2:B$217=A13)*'📋 Raw Data'!J$2:J$217) -> 364579.72
A14: سبتمبر | B14: =SUMPRODUCT(('📋 Raw Data'!B$2:B$217=A14)*'📋 Raw Data'!H$2:H$217) -> 821661.43 | C14: =SUMPRODUCT(('📋 Raw Data'!B$2:B$217=A14)*'📋 Raw Data'!J$2:J$217) -> 345696.05
A15: أكتوبر | B15: =SUMPRODUCT(('📋 Raw Data'!B$2:B$217=A15)*'📋 Raw Data'!H$2:H$217) -> 913664.59 | C15: =SUMPRODUCT(('📋 Raw Data'!B$2:B$217=A15)*'📋 Raw Data'!J$2:J$217) -> 384383.43
A16: نوفمبر | B16: =SUMPRODUCT(('📋 Raw Data'!B$2:B$217=A16)*'📋 Raw Data'!H$2:H$217) -> 929140.14 | C16: =SUMPRODUCT(('📋 Raw Data'!B$2:B$217=A16)*'📋 Raw Data'!J$2:J$217) -> 408642.74
A17: ديسمبر | B17: =SUMPRODUCT(('📋 Raw Data'!B$2:B$217=A17)*'📋 Raw Data'!H$2:H$217) -> 868092.28 | C17: =SUMPRODUCT(('📋 Raw Data'!B$2:B$217=A17)*'📋 Raw Data'!J$2:J$217) -> 367064.04
A20: بيانات المنتجات
A21: المنتج | B21: المبيعات | C21: الكمية
A22: لابتوب برو | B22: =SUMPRODUCT(('📋 Raw Data'!D$2:D$217=A22)*'📋 Raw Data'!H$2:H$217) -> 4212699.1 | C22: =SUMPRODUCT(('📋 Raw Data'!D$2:D$217=A22)*'📋 Raw Data'!F$2:F$217) -> 914
A23: هاتف سمارت | B23: =SUMPRODUCT(('📋 Raw Data'!D$2:D$217=A23)*'📋 Raw Data'!H$2:H$217) -> 2442295.1 | C23: =SUMPRODUCT(('📋 Raw Data'!D$2:D$217=A23)*'📋 Raw Data'!F$2:F$217) -> 872
A24: تابلت إكس | B24: =SUMPRODUCT(('📋 Raw Data'!D$2:D$217=A24)*'📋 Raw Data'!H$2:H$217) -> 1837139.6 | C24: =SUMPRODUCT(('📋 Raw Data'!D$2:D$217=A24)*'📋 Raw Data'!F$2:F$217) -> 952
A25: سماعات لاسلكية | B25: =SUMPRODUCT(('📋 Raw Data'!D$2:D$217=A25)*'📋 Raw Data'!H$2:H$217) -> 699892.69 | C25: =SUMPRODUCT(('📋 Raw Data'!D$2:D$217=A25)*'📋 Raw Data'!F$2:F$217) -> 1058
A26: ساعة ذكية | B26: =SUMPRODUCT(('📋 Raw Data'!D$2:D$217=A26)*'📋 Raw Data'!H$2:H$217) -> 1290315.3 | C26: =SUMPRODUCT(('📋 Raw Data'!D$2:D$217=A26)*'📋 Raw Data'!F$2:F$217) -> 1049
A30: بيانات المناطق
A31: المنطقة | B31: المبيعات
A32: الشمال | B32: =SUMPRODUCT(('📋 Raw Data'!C$2:C$217=A32)*'📋 Raw Data'!H$2:H$217) -> 1668953.3
A33: الجنوب | B33: =SUMPRODUCT(('📋 Raw Data'!C$2:C$217=A33)*'📋 Raw Data'!H$2:H$217) -> 1903985.1
A34: الشرق | B34: =SUMPRODUCT(('📋 Raw Data'!C$2:C$217=A34)*'📋 Raw Data'!H$2:H$217) -> 1983703.5
A35: الغرب | B35: =SUMPRODUCT(('📋 Raw Data'!C$2:C$217=A35)*'📋 Raw Data'!H$2:H$217) -> 2372972.3
A36: الوسط | B36: =SUMPRODUCT(('📋 Raw Data'!C$2:C$217=A36)*'📋 Raw Data'!H$2:H$217) -> 2552727.6
